
                    <!--
                    joint_number: 6
                    -->
                    <mujoco model="randomrobot">
                        <compiler angle="degree" coordinate="global" inertiafromgeom="true"/>
                        <default>
                        <joint armature="0.01" damping=".1" limited="true"/>
                        <geom conaffinity="0" condim="3" contype="1" density="1000" friction="0.8 .1 .1" rgba="0.8 0.6 .4 1"/>
                        </default>
                        <option integrator="RK4" timestep="0.002"/>
                        <worldbody>
                    <body name='torso' pos='0.00 0.00 0.89'><geom fromto='0 0 0 0.00 0.00 1.00' name='torso_geom' size='0.06' type='capsule'/><inertial mass='0.3'/><body name='L0_D1' pos='0.00 0.00 0.30'><joint axis='1 0 0' name='L0_D1_joint' pos='0 0 0' range='10.52 121.19' type='hinge'/><geom fromto='0 0 0 -0.19 0.52 -0.36' name='L0_D1_geom' size='0.06' type='capsule'/><inertial mass='0.3'/></body><body name='L1_D1' pos='0.00 0.00 0.09'><joint axis='0 1 0' name='L1_D1_joint' pos='0 0 0' range='84.14 85.45' type='hinge'/><geom fromto='0 0 0 0.16 -0.36 -0.38' name='L1_D1_geom' size='0.06' type='capsule'/><inertial mass='0.3'/></body><body name='L2_D1' pos='0.00 0.00 0.68'><joint axis='0 0 1' name='L2_D1_joint' pos='0 0 0' range='95.56 122.48' type='hinge'/><geom fromto='0 0 0 -0.45 0.08 0.10' name='L2_D1_geom' size='0.04' type='capsule'/><inertial mass='0.3'/><body name='L3_D0' pos='-0.11 0.02 0.02'><joint axis='0 1 0' name='L3_D0_joint' pos='0 0 0' range='80.08 130.80' type='hinge'/><geom fromto='0 0 0 -0.15 0.41 -0.23' name='L3_D0_geom' size='0.03' type='capsule'/><inertial mass='0.3'/></body></body><body name='L4_D1' pos='0.00 0.00 0.19'><joint axis='0 0 1' name='L4_D1_joint' pos='0 0 0' range='109.83 119.40' type='hinge'/><geom fromto='0 0 0 0.21 -0.17 0.40' name='L4_D1_geom' size='0.05' type='capsule'/><inertial mass='0.3'/><body name='L5_D0' pos='0.09 -0.07 0.18'><joint axis='0 0 1' name='L5_D0_joint' pos='0 0 0' range='67.21 115.97' type='hinge'/><geom fromto='0 0 0 -0.05 -0.32 -0.09' name='L5_D0_geom' size='0.05' type='capsule'/><inertial mass='0.3'/></body></body></body>
                        </worldbody>
                    </mujoco>
                    
