
                    <!--
                    joint_number: 6
                    -->
                    <mujoco model="randomrobot">
                        <compiler angle="degree" coordinate="global" inertiafromgeom="true"/>
                        <default>
                        <joint armature="0.01" damping=".1" limited="true"/>
                        <geom conaffinity="0" condim="3" contype="1" density="1000" friction="0.8 .1 .1" rgba="0.8 0.6 .4 1"/>
                        </default>
                        <option integrator="RK4" timestep="0.002"/>
                        <worldbody>
                    <body name='torso' pos='0.00 0.00 0.60'><geom fromto='0 0 0 0.00 0.00 1.00' name='torso_geom' size='0.06' type='capsule'/><inertial mass='0.3'/><body name='L0_D1' pos='0.00 0.00 0.42'><joint axis='1 0 0' name='L0_D1_joint' pos='0 0 0' range='68.56 89.68' type='hinge'/><geom fromto='0 0 0 0.08 -0.20 0.25' name='L0_D1_geom' size='0.05' type='capsule'/><inertial mass='0.3'/><body name='L1_D0' pos='0.03 -0.08 0.10'><joint axis='0 1 0' name='L1_D0_joint' pos='0 0 0' range='45.57 129.64' type='hinge'/><geom fromto='0 0 0 -0.05 -0.22 -0.42' name='L1_D0_geom' size='0.06' type='capsule'/><inertial mass='0.3'/></body><body name='L2_D0' pos='0.07 -0.18 0.22'><joint axis='1 0 0' name='L2_D0_joint' pos='0 0 0' range='10.53 25.63' type='hinge'/><geom fromto='0 0 0 0.33 -0.26 0.46' name='L2_D0_geom' size='0.05' type='capsule'/><inertial mass='0.3'/></body></body><body name='L3_D1' pos='0.00 0.00 0.99'><joint axis='0 0 1' name='L3_D1_joint' pos='0 0 0' range='48.60 91.92' type='hinge'/><geom fromto='0 0 0 0.77 0.13 0.48' name='L3_D1_geom' size='0.05' type='capsule'/><inertial mass='0.3'/><body name='L4_D0' pos='0.63 0.11 0.40'><joint axis='1 0 0' name='L4_D0_joint' pos='0 0 0' range='55.43 113.01' type='hinge'/><geom fromto='0 0 0 -0.16 0.16 0.61' name='L4_D0_geom' size='0.06' type='capsule'/><inertial mass='0.3'/></body><body name='L5_D0' pos='0.06 0.01 0.04'><joint axis='0 0 1' name='L5_D0_joint' pos='0 0 0' range='21.83 31.74' type='hinge'/><geom fromto='0 0 0 0.37 -0.29 -0.26' name='L5_D0_geom' size='0.05' type='capsule'/><inertial mass='0.3'/></body></body></body>
                        </worldbody>
                    </mujoco>
                    
