
                    <!--
                    joint_number: 6
                    -->
                    <mujoco model="randomrobot">
                        <compiler angle="degree" coordinate="global" inertiafromgeom="true"/>
                        <default>
                        <joint armature="0.01" damping=".1" limited="true"/>
                        <geom conaffinity="0" condim="3" contype="1" density="1000" friction="0.8 .1 .1" rgba="0.8 0.6 .4 1"/>
                        </default>
                        <option integrator="RK4" timestep="0.002"/>
                        <worldbody>
                    <body name='torso' pos='0.00 0.00 0.77'><geom fromto='0 0 0 0.00 0.00 1.00' name='torso_geom' size='0.06' type='capsule'/><inertial mass='0.3'/><body name='L0_D1' pos='0.00 0.00 0.38'><joint axis='1 0 0' name='L0_D1_joint' pos='0 0 0' range='13.43 50.57' type='hinge'/><geom fromto='0 0 0 0.49 0.58 0.05' name='L0_D1_geom' size='0.05' type='capsule'/><inertial mass='0.3'/><body name='L1_D0' pos='0.31 0.38 0.03'><joint axis='0 0 1' name='L1_D0_joint' pos='0 0 0' range='79.74 98.88' type='hinge'/><geom fromto='0 0 0 0.51 0.58 -0.59' name='L1_D0_geom' size='0.06' type='capsule'/><inertial mass='0.3'/></body></body><body name='L2_D1' pos='0.00 0.00 0.79'><joint axis='1 0 0' name='L2_D1_joint' pos='0 0 0' range='15.55 113.63' type='hinge'/><geom fromto='0 0 0 -0.34 0.44 0.17' name='L2_D1_geom' size='0.04' type='capsule'/><inertial mass='0.3'/><body name='L3_D0' pos='-0.20 0.26 0.10'><joint axis='0 0 1' name='L3_D0_joint' pos='0 0 0' range='58.32 72.31' type='hinge'/><geom fromto='0 0 0 0.34 -0.25 0.28' name='L3_D0_geom' size='0.05' type='capsule'/><inertial mass='0.3'/></body></body><body name='L4_D1' pos='0.00 0.00 0.69'><joint axis='0 1 0' name='L4_D1_joint' pos='0 0 0' range='24.36 112.79' type='hinge'/><geom fromto='0 0 0 0.33 -0.46 -0.53' name='L4_D1_geom' size='0.06' type='capsule'/><inertial mass='0.3'/><body name='L5_D0' pos='0.01 -0.01 -0.01'><joint axis='1 0 0' name='L5_D0_joint' pos='0 0 0' range='75.00 110.83' type='hinge'/><geom fromto='0 0 0 -0.22 -0.61 0.43' name='L5_D0_geom' size='0.07' type='capsule'/><inertial mass='0.3'/></body></body></body>
                        </worldbody>
                    </mujoco>
                    
