
                    <!--
                    joint_number: 6
                    -->
                    <mujoco model="randomrobot">
                        <compiler angle="degree" coordinate="global" inertiafromgeom="true"/>
                        <default>
                        <joint armature="0.01" damping=".1" limited="true"/>
                        <geom conaffinity="0" condim="3" contype="1" density="1000" friction="0.8 .1 .1" rgba="0.8 0.6 .4 1"/>
                        </default>
                        <option integrator="RK4" timestep="0.002"/>
                        <worldbody>
                    <body name='torso' pos='0.00 0.00 0.95'><geom fromto='0 0 0 0.00 0.00 1.00' name='torso_geom' size='0.06' type='capsule'/><inertial mass='0.3'/><body name='L0_D1' pos='0.00 0.00 0.15'><joint axis='0 1 0' name='L0_D1_joint' pos='0 0 0' range='1.36 32.69' type='hinge'/><geom fromto='0 0 0 -0.23 0.11 -0.10' name='L0_D1_geom' size='0.06' type='capsule'/><inertial mass='0.3'/><body name='L1_D0' pos='-0.02 0.01 -0.01'><joint axis='0 0 1' name='L1_D0_joint' pos='0 0 0' range='63.62 114.13' type='hinge'/><geom fromto='0 0 0 -0.19 0.47 -0.31' name='L1_D0_geom' size='0.06' type='capsule'/><inertial mass='0.3'/></body><body name='L2_D0' pos='-0.23 0.11 -0.10'><joint axis='0 0 1' name='L2_D0_joint' pos='0 0 0' range='123.77 128.82' type='hinge'/><geom fromto='0 0 0 -0.55 -0.65 -0.41' name='L2_D0_geom' size='0.03' type='capsule'/><inertial mass='0.3'/></body></body><body name='L3_D1' pos='0.00 0.00 0.55'><joint axis='0 0 1' name='L3_D1_joint' pos='0 0 0' range='41.50 129.03' type='hinge'/><geom fromto='0 0 0 -0.21 0.36 0.43' name='L3_D1_geom' size='0.06' type='capsule'/><inertial mass='0.3'/><body name='L4_D0' pos='-0.06 0.10 0.12'><joint axis='0 0 1' name='L4_D0_joint' pos='0 0 0' range='42.18 69.35' type='hinge'/><geom fromto='0 0 0 -0.30 0.17 -0.05' name='L4_D0_geom' size='0.03' type='capsule'/><inertial mass='0.3'/></body></body><body name='L5_D1' pos='0.00 0.00 0.45'><joint axis='1 0 0' name='L5_D1_joint' pos='0 0 0' range='31.51 37.94' type='hinge'/><geom fromto='0 0 0 -0.22 -0.24 -0.01' name='L5_D1_geom' size='0.06' type='capsule'/><inertial mass='0.3'/></body></body>
                        </worldbody>
                    </mujoco>
                    
